Workbook
Name Currency: 'Dish Input'!$F$3

Sheet Dashboard
E1: DISH PROFITABILITY TRACKER
B2: Dish Profitability Tracker | E2: Point Numera — pointnumera.com
B3: 📊 Dashboard | E3: [ Point Numera Logo ]
B4: 🍽️ Dish Input
B5: 📝 Notes
E6: TARGET FOOD COST %
E7: Target Food Cost % | F7: 0.3
E9: DISH SUMMARY
E10: Dish Name | F10: ="Selling Price ("&'Dish Input'!$F$3&")" -> Selling Price (CHF) | G10: Food Cost % | H10: ="Gross Margin ("&'Dish Input'!$F$3&")" -> Gross Margin (CHF) | I10: Gross Margin % | J10: Status
E11: ='Dish Input'!F7 -> Grilled Salmon Bowl | F11: ='Dish Input'!F10 -> 22.889908 | G11: ='Dish Input'!J27 -> 0.20205411 | H11: ='Dish Input'!J28 -> 18.264908 | I11: ='Dish Input'!J29 -> 0.79794589 | J11: =IF(F11=0,"—",IF(G11<=$F$7,"✅ On Target",IF(G11<=$F$7+0.05,"⚠ Watch","❌ Over"))) -> ✅ On Target
E12: ='Dish Input'!F33 -> Margherita Pizza | F12: ='Dish Input'!F36 -> 15.137615 | G12: ='Dish Input'!J53 -> 0.20373091 | H12: ='Dish Input'!J54 -> 12.053615 | I12: ='Dish Input'!J55 -> 0.79626909 | J12: =IF(F12=0,"—",IF(G12<=$F$7,"✅ On Target",IF(G12<=$F$7+0.05,"⚠ Watch","❌ Over"))) -> ✅ On Target
E13: ='Dish Input'!F59 -> Dish 3 | F13: ='Dish Input'!F62 -> 0 | G13: ='Dish Input'!J79 -> 0 | H13: ='Dish Input'!J80 -> 0 | I13: ='Dish Input'!J81 -> 0 | J13: =IF(F13=0,"—",IF(G13<=$F$7,"✅ On Target",IF(G13<=$F$7+0.05,"⚠ Watch","❌ Over"))) -> —
E14: ='Dish Input'!F85 -> Dish 4 | F14: ='Dish Input'!F88 -> 0 | G14: ='Dish Input'!J105 -> 0 | H14: ='Dish Input'!J106 -> 0 | I14: ='Dish Input'!J107 -> 0 | J14: =IF(F14=0,"—",IF(G14<=$F$7,"✅ On Target",IF(G14<=$F$7+0.05,"⚠ Watch","❌ Over"))) -> —
E15: ='Dish Input'!F111 -> Dish 5 | F15: ='Dish Input'!F114 -> 0 | G15: ='Dish Input'!J131 -> 0 | H15: ='Dish Input'!J132 -> 0 | I15: ='Dish Input'!J133 -> 0 | J15: =IF(F15=0,"—",IF(G15<=$F$7,"✅ On Target",IF(G15<=$F$7+0.05,"⚠ Watch","❌ Over"))) -> —
E17: AVERAGES | F17: Avg Food Cost %: | G17: =IFERROR(AVERAGEIF(F11:F15,">0",G11:G15),0) -> 0.20289251 | H17: Avg Gross Margin %: | I17: =IFERROR(AVERAGEIF(F11:F15,">0",I11:I15),0) -> 0.79710749
E19: COST vs MARGIN BREAKDOWN
E20: Avg Food Cost % | F20: Avg Gross Margin %
E21: =G17 -> 0.20289251 | F21: =I17 -> 0.79710749
E23: PRICE COMPOSITION
E24: Select Dish: | F24: Grilled Salmon Bowl | G24: =IFERROR(MATCH(F24,$E$11:$E$15,0),1) -> 1
E25: Component | F25: % of Selling Price | G25: ="Cost ("&'Dish Input'!$F$3&")" -> Cost (CHF)
E26: =IFERROR(IF(CHOOSE($G$24,'Dish Input'!E13,'Dish Input'!E39,'Dish Input'!E65,'Dish Input'!E91,'Dish Input'!E117)=0,"",CHOOSE($G$24,'Dish Input'!E13,'Dish Input'!E39,'Dish Input'!E65,'Dish Input'!E91,'Dish Input'!E117)),"") -> Salmon fillet | F26: =IF(E26="","",IFERROR(CHOOSE($G$24,'Dish Input'!J13,'Dish Input'!J39,'Dish Input'!J65,'Dish Input'!J91,'Dish Input'!J117)/CHOOSE($G$24,'Dish Input'!F10,'Dish Input'!F36,'Dish Input'!F62,'Dish Input'!F88,'Dish Input'!F114),0)) -> 0.078637275 | G26: =IF(E26="","",IFERROR(CHOOSE($G$24,'Dish Input'!J13,'Dish Input'!J39,'Dish Input'!J65,'Dish Input'!J91,'Dish Input'!J117),0)) -> 1.8
E27: =IFERROR(IF(CHOOSE($G$24,'Dish Input'!E14,'Dish Input'!E40,'Dish Input'!E66,'Dish Input'!E92,'Dish Input'!E118)=0,"",CHOOSE($G$24,'Dish Input'!E14,'Dish Input'!E40,'Dish Input'!E66,'Dish Input'!E92,'Dish Input'!E118)),"") -> Basmati rice | F27: =IF(E27="","",IFERROR(CHOOSE($G$24,'Dish Input'!J14,'Dish Input'!J40,'Dish Input'!J66,'Dish Input'!J92,'Dish Input'!J118)/CHOOSE($G$24,'Dish Input'!F10,'Dish Input'!F36,'Dish Input'!F62,'Dish Input'!F88,'Dish Input'!F114),0)) -> 0.015727455 | G27: =IF(E27="","",IFERROR(CHOOSE($G$24,'Dish Input'!J14,'Dish Input'!J40,'Dish Input'!J66,'Dish Input'!J92,'Dish Input'!J118),0)) -> 0.36
E28: =IFERROR(IF(CHOOSE($G$24,'Dish Input'!E15,'Dish Input'!E41,'Dish Input'!E67,'Dish Input'!E93,'Dish Input'!E119)=0,"",CHOOSE($G$24,'Dish Input'!E15,'Dish Input'!E41,'Dish Input'!E67,'Dish Input'!E93,'Dish Input'!E119)),"") -> Avocado | F28: =IF(E28="","",IFERROR(CHOOSE($G$24,'Dish Input'!J15,'Dish Input'!J41,'Dish Input'!J67,'Dish Input'!J93,'Dish Input'!J119)/CHOOSE($G$24,'Dish Input'!F10,'Dish Input'!F36,'Dish Input'!F62,'Dish Input'!F88,'Dish Input'!F114),0)) -> 0.05242485 | G28: =IF(E28="","",IFERROR(CHOOSE($G$24,'Dish Input'!J15,'Dish Input'!J41,'Dish Input'!J67,'Dish Input'!J93,'Dish Input'!J119),0)) -> 1.2
E29: =IFERROR(IF(CHOOSE($G$24,'Dish Input'!E16,'Dish Input'!E42,'Dish Input'!E68,'Dish Input'!E94,'Dish Input'!E120)=0,"",CHOOSE($G$24,'Dish Input'!E16,'Dish Input'!E42,'Dish Input'!E68,'Dish Input'!E94,'Dish Input'!E120)),"") -> Edamame | F29: =IF(E29="","",IFERROR(CHOOSE($G$24,'Dish Input'!J16,'Dish Input'!J42,'Dish Input'!J68,'Dish Input'!J94,'Dish Input'!J120)/CHOOSE($G$24,'Dish Input'!F10,'Dish Input'!F36,'Dish Input'!F62,'Dish Input'!F88,'Dish Input'!F114),0)) -> 0.01747495 | G29: =IF(E29="","",IFERROR(CHOOSE($G$24,'Dish Input'!J16,'Dish Input'!J42,'Dish Input'!J68,'Dish Input'!J94,'Dish Input'!J120),0)) -> 0.4
E30: =IFERROR(IF(CHOOSE($G$24,'Dish Input'!E17,'Dish Input'!E43,'Dish Input'!E69,'Dish Input'!E95,'Dish Input'!E121)=0,"",CHOOSE($G$24,'Dish Input'!E17,'Dish Input'!E43,'Dish Input'!E69,'Dish Input'!E95,'Dish Input'!E121)),"") -> Sesame dressing | F30: =IF(E30="","",IFERROR(CHOOSE($G$24,'Dish Input'!J17,'Dish Input'!J43,'Dish Input'!J69,'Dish Input'!J95,'Dish Input'!J121)/CHOOSE($G$24,'Dish Input'!F10,'Dish Input'!F36,'Dish Input'!F62,'Dish Input'!F88,'Dish Input'!F114),0)) -> 0.015727455 | G30: =IF(E30="","",IFERROR(CHOOSE($G$24,'Dish Input'!J17,'Dish Input'!J43,'Dish Input'!J69,'Dish Input'!J95,'Dish Input'!J121),0)) -> 0.36
E31: =IFERROR(IF(CHOOSE($G$24,'Dish Input'!E18,'Dish Input'!E44,'Dish Input'!E70,'Dish Input'!E96,'Dish Input'!E122)=0,"",CHOOSE($G$24,'Dish Input'!E18,'Dish Input'!E44,'Dish Input'!E70,'Dish Input'!E96,'Dish Input'!E122)),"") -> Spring onion | F31: =IF(E31="","",IFERROR(CHOOSE($G$24,'Dish Input'!J18,'Dish Input'!J44,'Dish Input'!J70,'Dish Input'!J96,'Dish Input'!J122)/CHOOSE($G$24,'Dish Input'!F10,'Dish Input'!F36,'Dish Input'!F62,'Dish Input'!F88,'Dish Input'!F114),0)) -> 0.0021843687 | G31: =IF(E31="","",IFERROR(CHOOSE($G$24,'Dish Input'!J18,'Dish Input'!J44,'Dish Input'!J70,'Dish Input'!J96,'Dish Input'!J122),0)) -> 0.05
E32: =IFERROR(IF(CHOOSE($G$24,'Dish Input'!E19,'Dish Input'!E45,'Dish Input'!E71,'Dish Input'!E97,'Dish Input'!E123)=0,"",CHOOSE($G$24,'Dish Input'!E19,'Dish Input'!E45,'Dish Input'!E71,'Dish Input'!E97,'Dish Input'!E123)),"") -> Sesame seeds | F32: =IF(E32="","",IFERROR(CHOOSE($G$24,'Dish Input'!J19,'Dish Input'!J45,'Dish Input'!J71,'Dish Input'!J97,'Dish Input'!J123)/CHOOSE($G$24,'Dish Input'!F10,'Dish Input'!F36,'Dish Input'!F62,'Dish Input'!F88,'Dish Input'!F114),0)) -> 0.0054609218 | G32: =IF(E32="","",IFERROR(CHOOSE($G$24,'Dish Input'!J19,'Dish Input'!J45,'Dish Input'!J71,'Dish Input'!J97,'Dish Input'!J123),0)) -> 0.125
E33: =IFERROR(IF(CHOOSE($G$24,'Dish Input'!E20,'Dish Input'!E46,'Dish Input'!E72,'Dish Input'!E98,'Dish Input'!E124)=0,"",CHOOSE($G$24,'Dish Input'!E20,'Dish Input'!E46,'Dish Input'!E72,'Dish Input'!E98,'Dish Input'!E124)),"") -> Lime wedge | F33: =IF(E33="","",IFERROR(CHOOSE($G$24,'Dish Input'!J20,'Dish Input'!J46,'Dish Input'!J72,'Dish Input'!J98,'Dish Input'!J124)/CHOOSE($G$24,'Dish Input'!F10,'Dish Input'!F36,'Dish Input'!F62,'Dish Input'!F88,'Dish Input'!F114),0)) -> 0.0065531062 | G33: =IF(E33="","",IFERROR(CHOOSE($G$24,'Dish Input'!J20,'Dish Input'!J46,'Dish Input'!J72,'Dish Input'!J98,'Dish Input'!J124),0)) -> 0.15
E34: =IFERROR(IF(CHOOSE($G$24,'Dish Input'!E21,'Dish Input'!E47,'Dish Input'!E73,'Dish Input'!E99,'Dish Input'!E125)=0,"",CHOOSE($G$24,'Dish Input'!E21,'Dish Input'!E47,'Dish Input'!E73,'Dish Input'!E99,'Dish Input'!E125)),"") -> Soy sauce | F34: =IF(E34="","",IFERROR(CHOOSE($G$24,'Dish Input'!J21,'Dish Input'!J47,'Dish Input'!J73,'Dish Input'!J99,'Dish Input'!J125)/CHOOSE($G$24,'Dish Input'!F10,'Dish Input'!F36,'Dish Input'!F62,'Dish Input'!F88,'Dish Input'!F114),0)) -> 0.0026212425 | G34: =IF(E34="","",IFERROR(CHOOSE($G$24,'Dish Input'!J21,'Dish Input'!J47,'Dish Input'!J73,'Dish Input'!J99,'Dish Input'!J125),0)) -> 0.06
E35: =IFERROR(IF(CHOOSE($G$24,'Dish Input'!E22,'Dish Input'!E48,'Dish Input'!E74,'Dish Input'!E100,'Dish Input'!E126)=0,"",CHOOSE($G$24,'Dish Input'!E22,'Dish Input'!E48,'Dish Input'!E74,'Dish Input'!E100,'Dish Input'!E126)),"") -> Pickled ginger | F35: =IF(E35="","",IFERROR(CHOOSE($G$24,'Dish Input'!J22,'Dish Input'!J48,'Dish Input'!J74,'Dish Input'!J100,'Dish Input'!J126)/CHOOSE($G$24,'Dish Input'!F10,'Dish Input'!F36,'Dish Input'!F62,'Dish Input'!F88,'Dish Input'!F114),0)) -> 0.005242485 | G35: =IF(E35="","",IFERROR(CHOOSE($G$24,'Dish Input'!J22,'Dish Input'!J48,'Dish Input'!J74,'Dish Input'!J100,'Dish Input'!J126),0)) -> 0.12
E36: =IFERROR(IF(CHOOSE($G$24,'Dish Input'!E23,'Dish Input'!E49,'Dish Input'!E75,'Dish Input'!E101,'Dish Input'!E127)=0,"",CHOOSE($G$24,'Dish Input'!E23,'Dish Input'!E49,'Dish Input'!E75,'Dish Input'!E101,'Dish Input'!E127)),"") | F36: =IF(E36="","",IFERROR(CHOOSE($G$24,'Dish Input'!J23,'Dish Input'!J49,'Dish Input'!J75,'Dish Input'!J101,'Dish Input'!J127)/CHOOSE($G$24,'Dish Input'!F10,'Dish Input'!F36,'Dish Input'!F62,'Dish Input'!F88,'Dish Input'!F114),0)) | G36: =IF(E36="","",IFERROR(CHOOSE($G$24,'Dish Input'!J23,'Dish Input'!J49,'Dish Input'!J75,'Dish Input'!J101,'Dish Input'!J127),0))
E37: =IFERROR(IF(CHOOSE($G$24,'Dish Input'!E24,'Dish Input'!E50,'Dish Input'!E76,'Dish Input'!E102,'Dish Input'!E128)=0,"",CHOOSE($G$24,'Dish Input'!E24,'Dish Input'!E50,'Dish Input'!E76,'Dish Input'!E102,'Dish Input'!E128)),"") | F37: =IF(E37="","",IFERROR(CHOOSE($G$24,'Dish Input'!J24,'Dish Input'!J50,'Dish Input'!J76,'Dish Input'!J102,'Dish Input'!J128)/CHOOSE($G$24,'Dish Input'!F10,'Dish Input'!F36,'Dish Input'!F62,'Dish Input'!F88,'Dish Input'!F114),0)) | G37: =IF(E37="","",IFERROR(CHOOSE($G$24,'Dish Input'!J24,'Dish Input'!J50,'Dish Input'!J76,'Dish Input'!J102,'Dish Input'!J128),0))
E38: Gross Margin | F38: =IFERROR(CHOOSE($G$24,'Dish Input'!J28,'Dish Input'!J54,'Dish Input'!J80,'Dish Input'!J106,'Dish Input'!J132)/CHOOSE($G$24,'Dish Input'!F10,'Dish Input'!F36,'Dish Input'!F62,'Dish Input'!F88,'Dish Input'!F114),0) -> 0.79794589 | G38: =IFERROR(CHOOSE($G$24,'Dish Input'!J28,'Dish Input'!J54,'Dish Input'!J80,'Dish Input'!J106,'Dish Input'!J132),0) -> 18.264908

Sheet Dish Input
E1: DISH INPUT
B2: Dish Profitability Tracker | E2: Enter dish details and ingredients. Blue values are editable
B3: 📊 Dashboard | E3: Currency: | F3: CHF
B4: 🍽️ Dish Input
B5: 📝 Notes
E6: DISH 1
E7: Dish Name | F7: Grilled Salmon Bowl
E8: Selling Price (incl. VAT) | F8: 24.95
E9: VAT Rate % | F9: 0.09
E10: Price excl. VAT | F10: =IFERROR(F8/(1+F9),0) -> 22.889908
E12: Ingredient | F12: Qty | G12: Unit | H12: ="Cost / Bulk ("&$F$3&")" -> Cost / Bulk (CHF) | I12: Bulk Unit | J12: ="Cost / Portion ("&$F$3&")" -> Cost / Portion (CHF)
E13: Salmon fillet | F13: 180 | G13: g | H13: 10 | I13: =IF(G13="","",IF(G13="g","per kg",IF(G13="ml","per L",IF(G13="oz","per lb",IF(G13="kg","per kg",IF(G13="L","per L",IF(G13="lb","per lb",IF(G13="fl oz","per fl oz","per unit")))))))) -> per kg | J13: =IF(F13="","",IF(OR(G13="g",G13="ml"),H13/1000*F13,IF(G13="oz",H13/16*F13,H13*F13))) -> 1.8
E14: Basmati rice | F14: 120 | G14: g | H14: 3 | I14: =IF(G14="","",IF(G14="g","per kg",IF(G14="ml","per L",IF(G14="oz","per lb",IF(G14="kg","per kg",IF(G14="L","per L",IF(G14="lb","per lb",IF(G14="fl oz","per fl oz","per unit")))))))) -> per kg | J14: =IF(F14="","",IF(OR(G14="g",G14="ml"),H14/1000*F14,IF(G14="oz",H14/16*F14,H14*F14))) -> 0.36
E15: Avocado | F15: 80 | G15: g | H15: 15 | I15: =IF(G15="","",IF(G15="g","per kg",IF(G15="ml","per L",IF(G15="oz","per lb",IF(G15="kg","per kg",IF(G15="L","per L",IF(G15="lb","per lb",IF(G15="fl oz","per fl oz","per unit")))))))) -> per kg | J15: =IF(F15="","",IF(OR(G15="g",G15="ml"),H15/1000*F15,IF(G15="oz",H15/16*F15,H15*F15))) -> 1.2
E16: Edamame | F16: 50 | G16: g | H16: 8 | I16: =IF(G16="","",IF(G16="g","per kg",IF(G16="ml","per L",IF(G16="oz","per lb",IF(G16="kg","per kg",IF(G16="L","per L",IF(G16="lb","per lb",IF(G16="fl oz","per fl oz","per unit")))))))) -> per kg | J16: =IF(F16="","",IF(OR(G16="g",G16="ml"),H16/1000*F16,IF(G16="oz",H16/16*F16,H16*F16))) -> 0.4
E17: Sesame dressing | F17: 30 | G17: ml | H17: 12 | I17: =IF(G17="","",IF(G17="g","per kg",IF(G17="ml","per L",IF(G17="oz","per lb",IF(G17="kg","per kg",IF(G17="L","per L",IF(G17="lb","per lb",IF(G17="fl oz","per fl oz","per unit")))))))) -> per L | J17: =IF(F17="","",IF(OR(G17="g",G17="ml"),H17/1000*F17,IF(G17="oz",H17/16*F17,H17*F17))) -> 0.36
E18: Spring onion | F18: 10 | G18: g | H18: 5 | I18: =IF(G18="","",IF(G18="g","per kg",IF(G18="ml","per L",IF(G18="oz","per lb",IF(G18="kg","per kg",IF(G18="L","per L",IF(G18="lb","per lb",IF(G18="fl oz","per fl oz","per unit")))))))) -> per kg | J18: =IF(F18="","",IF(OR(G18="g",G18="ml"),H18/1000*F18,IF(G18="oz",H18/16*F18,H18*F18))) -> 0.05
E19: Sesame seeds | F19: 5 | G19: g | H19: 25 | I19: =IF(G19="","",IF(G19="g","per kg",IF(G19="ml","per L",IF(G19="oz","per lb",IF(G19="kg","per kg",IF(G19="L","per L",IF(G19="lb","per lb",IF(G19="fl oz","per fl oz","per unit")))))))) -> per kg | J19: =IF(F19="","",IF(OR(G19="g",G19="ml"),H19/1000*F19,IF(G19="oz",H19/16*F19,H19*F19))) -> 0.125
E20: Lime wedge | F20: 1 | G20: pcs | H20: 0.15 | I20: =IF(G20="","",IF(G20="g","per kg",IF(G20="ml","per L",IF(G20="oz","per lb",IF(G20="kg","per kg",IF(G20="L","per L",IF(G20="lb","per lb",IF(G20="fl oz","per fl oz","per unit")))))))) -> per unit | J20: =IF(F20="","",IF(OR(G20="g",G20="ml"),H20/1000*F20,IF(G20="oz",H20/16*F20,H20*F20))) -> 0.15
E21: Soy sauce | F21: 15 | G21: ml | H21: 4 | I21: =IF(G21="","",IF(G21="g","per kg",IF(G21="ml","per L",IF(G21="oz","per lb",IF(G21="kg","per kg",IF(G21="L","per L",IF(G21="lb","per lb",IF(G21="fl oz","per fl oz","per unit")))))))) -> per L | J21: =IF(F21="","",IF(OR(G21="g",G21="ml"),H21/1000*F21,IF(G21="oz",H21/16*F21,H21*F21))) -> 0.06
E22: Pickled ginger | F22: 10 | G22: g | H22: 12 | I22: =IF(G22="","",IF(G22="g","per kg",IF(G22="ml","per L",IF(G22="oz","per lb",IF(G22="kg","per kg",IF(G22="L","per L",IF(G22="lb","per lb",IF(G22="fl oz","per fl oz","per unit")))))))) -> per kg | J22: =IF(F22="","",IF(OR(G22="g",G22="ml"),H22/1000*F22,IF(G22="oz",H22/16*F22,H22*F22))) -> 0.12
I23: =IF(G23="","",IF(G23="g","per kg",IF(G23="ml","per L",IF(G23="oz","per lb",IF(G23="kg","per kg",IF(G23="L","per L",IF(G23="lb","per lb",IF(G23="fl oz","per fl oz","per unit")))))))) | J23: =IF(F23="","",IF(OR(G23="g",G23="ml"),H23/1000*F23,IF(G23="oz",H23/16*F23,H23*F23)))
I24: =IF(G24="","",IF(G24="g","per kg",IF(G24="ml","per L",IF(G24="oz","per lb",IF(G24="kg","per kg",IF(G24="L","per L",IF(G24="lb","per lb",IF(G24="fl oz","per fl oz","per unit")))))))) | J24: =IF(F24="","",IF(OR(G24="g",G24="ml"),H24/1000*F24,IF(G24="oz",H24/16*F24,H24*F24)))
E26: Total Ingredient Cost | J26: =SUM(J13:J24) -> 4.625
E27: Food Cost % | J27: =IFERROR(J26/F10,0) -> 0.20205411
E28: Gross Margin | J28: =F10-J26 -> 18.264908
E29: Gross Margin % | J29: =IFERROR(J28/F10,0) -> 0.79794589
E30: Biggest Cost Driver | J30: =IFERROR(INDEX(E13:E24,MATCH(MAX(J13:J24),J13:J24,0)),"-") -> Salmon fillet
E31: Target Food Cost % | J31: =Dashboard!F7 -> 0.3
E32: DISH 2
E33: Dish Name | F33: Margherita Pizza
E34: Selling Price (incl. VAT) | F34: 16.5
E35: VAT Rate % | F35: 0.09
E36: Price excl. VAT | F36: =IFERROR(F34/(1+F35),0) -> 15.137615
E38: Ingredient | F38: Qty | G38: Unit | H38: ="Cost / Bulk ("&$F$3&")" -> Cost / Bulk (CHF) | I38: Bulk Unit | J38: ="Cost / Portion ("&$F$3&")" -> Cost / Portion (CHF)
E39: Pizza dough | F39: 250 | G39: g | H39: 2 | I39: =IF(G39="","",IF(G39="g","per kg",IF(G39="ml","per L",IF(G39="oz","per lb",IF(G39="kg","per kg",IF(G39="L","per L",IF(G39="lb","per lb",IF(G39="fl oz","per fl oz","per unit")))))))) -> per kg | J39: =IF(F39="","",IF(OR(G39="g",G39="ml"),H39/1000*F39,IF(G39="oz",H39/16*F39,H39*F39))) -> 0.5
E40: Mozzarella | F40: 125 | G40: g | H40: 12 | I40: =IF(G40="","",IF(G40="g","per kg",IF(G40="ml","per L",IF(G40="oz","per lb",IF(G40="kg","per kg",IF(G40="L","per L",IF(G40="lb","per lb",IF(G40="fl oz","per fl oz","per unit")))))))) -> per kg | J40: =IF(F40="","",IF(OR(G40="g",G40="ml"),H40/1000*F40,IF(G40="oz",H40/16*F40,H40*F40))) -> 1.5
E41: Tomato sauce | F41: 80 | G41: ml | H41: 5 | I41: =IF(G41="","",IF(G41="g","per kg",IF(G41="ml","per L",IF(G41="oz","per lb",IF(G41="kg","per kg",IF(G41="L","per L",IF(G41="lb","per lb",IF(G41="fl oz","per fl oz","per unit")))))))) -> per L | J41: =IF(F41="","",IF(OR(G41="g",G41="ml"),H41/1000*F41,IF(G41="oz",H41/16*F41,H41*F41))) -> 0.4
E42: Fresh basil | F42: 5 | G42: g | H42: 30 | I42: =IF(G42="","",IF(G42="g","per kg",IF(G42="ml","per L",IF(G42="oz","per lb",IF(G42="kg","per kg",IF(G42="L","per L",IF(G42="lb","per lb",IF(G42="fl oz","per fl oz","per unit")))))))) -> per kg | J42: =IF(F42="","",IF(OR(G42="g",G42="ml"),H42/1000*F42,IF(G42="oz",H42/16*F42,H42*F42))) -> 0.15
E43: Olive oil | F43: 15 | G43: ml | H43: 10 | I43: =IF(G43="","",IF(G43="g","per kg",IF(G43="ml","per L",IF(G43="oz","per lb",IF(G43="kg","per kg",IF(G43="L","per L",IF(G43="lb","per lb",IF(G43="fl oz","per fl oz","per unit")))))))) -> per L | J43: =IF(F43="","",IF(OR(G43="g",G43="ml"),H43/1000*F43,IF(G43="oz",H43/16*F43,H43*F43))) -> 0.15
...

Sheet Notes
E1: NOTES
B2: Dish Profitability Tracker | E2: Reference guide and contact information
B3: 📊 Dashboard
B4: 🍽️ Dish Input | E4: WHAT IS FOOD COST %?
B5: 📝 Notes | E5: Food Cost % measures the proportion of a dish's selling price (excl. VAT) that goes toward ingredient costs.
E6: Formula: Food Cost % = Total Ingredient Cost ÷ Dish Price excl. VAT
E7: A lower food cost % means higher profitability per dish. Industry benchmarks typically range from 25% to 35%.
E9: HOW TO USE THIS TRACKER
E10: 1. Set your Target Food Cost % on the Dashboard sheet (default: 30%).
E11: 2. Go to the Dish Input sheet and enter your dish name and selling price (incl. VAT) for each dish.
E12: 3. Enter each ingredient: name, quantity, unit (g / ml / pcs), and cost per unit.
E13: 4. All calculations are automatic, food cost %, gross margin, and the biggest cost driver update instantly.
E14: 5. Return to the Dashboard to see all dishes compared side-by-side with status indicators.
E15: 6. Green = on target, Amber = within 5 percentage points above target, Red = more than 5pp above target.
E16: 7. The donut chart shows the average food cost % vs gross margin % across all active dishes.
E17: 8. The pie chart shows the ingredient-level breakdown of Dish 1 as a proportion of the selling price.
E19: IMPORTANT
... E26: Book a Clarity Call
